Workbook

Sheet Assumptions
A1: ∆P (Delta P) — Financial Model (Conservative)
A2: All assumptions deliberately pessimistic. Designed to underpromise.
A3: Source: PFF Quote OFR000388 (Dec 2025) | EUR/USD 1.22 (pessimistic)
A5: COMPONENT COSTS (Ex-Works France, 30% volume discount)
A6: Component | B6: Reference | C6: List (EUR) | D6: Discount | E6: Net (EUR) | F6: Source
A7: Head V2 (Tête de Capsule V2) | B7: BV-TCAPSV2 | C7: 110 | D7: 0.3 | E7: =C7*(1-D7) -> 77 | F7: PFF OFR000388 (Dec 2025)
A8: Cartridge 0.450L Alu | B8: BI-BOE-CART8 | C8: 95 | D8: 0.3 | E8: =C8*(1-D8) -> 66.5 | F8: PFF OFR000388
A9: Gauge (Analog 50B) | B9: BV-ADSUSP-40B | C9: 96.5 | D9: 0.3 | E9: =C9*(1-D9) -> 67.55 | F9: PFF OFR000388
A10: Ramp (Chargement Azote) | B10: BV-RPAZOTE160B | C10: 440 | D10: 0.3 | E10: =C10*(1-D10) -> 308 | F10: PFF OFR000388
A11: TOTAL COMPONENTS | C11: =SUM(C7:C10) -> 741.5 | E11: =SUM(E7:E10) -> 519.05
A13: EXCHANGE RATE & TARIFFS
A14: EUR/USD exchange rate | B14: 1.22 | C14: Pessimistic (actual ~1.18, was 1.20)
A15: Tariff — Aluminum parts (Head, Cart.) | B15: 0.2
A16: Tariff — Standard parts (Gauge, Ramp) | B16: 0.15
A18: LANDED COSTS (USD)
A19: Component | B19: EUR Net | C19: USD Ex-Works | D19: Tariff Rate | E19: Landed USD
A20: Head V2 | B20: =E7 -> 77 | C20: =B20*$B$14 -> 93.94 | D20: =$B$15 -> 0.2 | E20: =C20*(1+D20) -> 112.728
A21: Cartridge | B21: =E8 -> 66.5 | C21: =B21*$B$14 -> 81.13 | D21: =$B$15 -> 0.2 | E21: =C21*(1+D21) -> 97.356
A22: Gauge | B22: =E9 -> 67.55 | C22: =B22*$B$14 -> 82.411 | D22: =$B$16 -> 0.15 | E22: =C22*(1+D22) -> 94.77265
A23: Ramp | B23: =E10 -> 308 | C23: =B23*$B$14 -> 375.76 | D23: =$B$16 -> 0.15 | E23: =C23*(1+D23) -> 432.124
A25: SHIPPING (France → Florida)
A26: Consumer kit shipping (per unit) | B26: 40 | C26: Conservative (was $30)
A27: Starter kit shipping (per unit) | B27: 65 | C27: Conservative (was $50)
A29: KIT COGS (Landed Florida)
A30: Consumer Kit COGS (Head + Cart. + ship) | B30: =E20+E21+B26 -> 250.084
A31: Starter Kit COGS (All 4 + ship) | B31: =E20+E21+E22+E23+B27 -> 801.98065
A33: PRICING
A34: Consumer Kit retail | B34: 849
A35: Starter Kit (regular) | B35: 1499
A36: Starter Kit (pre-launch, first 25 partners) | B36: 999
A37: Pre-launch partners (count) | B37: 25 | C37: Conservative (was 20)
A39: PARTNER COMMISSIONS
A40: Tier | B40: Units/Qtr | C40: Comm % | D40: Wholesale | E40: Nimbus Gross/Unit
A41: Tier 1 | B41: 1-10 | C41: 0.25 | D41: =$B$34*(1-C41) -> 636.75 | E41: =D41-$B$30 -> 386.666
A42: Tier 2 | B42: 11-30 | C42: 0.35 | D42: =$B$34*(1-C42) -> 551.85 | E42: =D42-$B$30 -> 301.766
A43: Tier 3 | B43: 31+ | C43: 0.4 | D43: =$B$34*(1-C43) -> 509.4 | E43: =D43-$B$30 -> 259.316
A45: REFILL ECONOMICS
A46: Nimbus fee per refill | B46: 3
A47: Capture rate (% reported) | B47: 0.6 | C47: Conservative — assumes 40% cheating
A48: Effective fee per refill | B48: =B46*B47 -> 1.8
...

Sheet Revenue Model
A1: ∆P — 18-Month Revenue Model (Conservative Base)
A2: Refills driven by installed cartridge base, not arbitrary ramp
B4: Jun-26 | C4: Jul-26 | D4: Aug-26 | E4: Sep-26 | F4: Oct-26 | G4: Nov-26 | H4: Dec-26 | I4: Jan-27 | J4: Feb-27 | K4: Mar-27 | L4: Apr-27 | M4: May-27 | N4: Jun-27 | O4: Jul-27 | P4: Aug-27 | Q4: Sep-27 | R4: Oct-27 | S4: Nov-27 | T4: 18-Mo Total
A5: PARTNER GROWTH
A6: New Partners | B6: =Assumptions!$B$71 -> 8 | C6: =Assumptions!$B$71 -> 8 | D6: =Assumptions!$B$71 -> 8 | E6: =Assumptions!$B$71 -> 8 | F6: =Assumptions!$B$71 -> 8 | G6: =Assumptions!$B$71 -> 8 | H6: =Assumptions!$B$71 -> 8 | I6: =Assumptions!$B$71 -> 8 | ... S6: =Assumptions!$B$71 -> 8
A7: Cumulative Partners | B7: =B6 -> 8 | C7: =B7+C6 -> 16 | D7: =C7+D6 -> 24 | E7: =D7+E6 -> 32 | F7: =E7+F6 -> 40 | G7: =F7+G6 -> 48 | H7: =G7+H6 -> 56 | I7: =H7+I6 -> 64 | J7: =I7+J6 -> 72 | ... S7: =R7+S6 -> 144 | T7: =S7 -> 144
A9: HARDWARE UNITS (3-month delay from signup)
A10: Units — selling 1-2 months | B10: 0 | C10: 0 | D10: 0 | E10: =1*Assumptions!$B$71*Assumptions!$B$65 -> 8 | F10: =2*Assumptions!$B$71*Assumptions!$B$65 -> 16 | G10: =2*Assumptions!$B$71*Assumptions!$B$65 -> 16 | H10: =2*Assumptions!$B$71*Assumptions!$B$65 -> 16 | I10: =2*Assumptions!$B$71*Assumptions!$B$65 -> 16 | J10: =2*Assumptions!$B$71*Assumptions!$B$65 -> 16 | K10: =2*Assumptions!$B$71*Assumptions!$B$65 -> 16 | L10: =2*Assumptions!$B$71*Assumptions!$B$65 -> 16 | M10: =2*Assumptions!$B$71*Assumptions!$B$65 -> 16 | ... S10: =2*Assumptions!$B$71*Assumptions!$B$65 -> 16
A11: Units — selling 3-5 months | B11: 0 | C11: 0 | D11: 0 | E11: 0 | F11: 0 | G11: =1*Assumptions!$B$71*Assumptions!$B$66 -> 16 | H11: =2*Assumptions!$B$71*Assumptions!$B$66 -> 32 | I11: =3*Assumptions!$B$71*Assumptions!$B$66 -> 48 | J11: =3*Assumptions!$B$71*Assumptions!$B$66 -> 48 | K11: =3*Assumptions!$B$71*Assumptions!$B$66 -> 48 | L11: =3*Assumptions!$B$71*Assumptions!$B$66 -> 48 | M11: =3*Assumptions!$B$71*Assumptions!$B$66 -> 48 | N11: =3*Assumptions!$B$71*Assumptions!$B$66 -> 48 | O11: =3*Assumptions!$B$71*Assumptions!$B$66 -> 48 | P11: =3*Assumptions!$B$71*Assumptions!$B$66 -> 48 | ... S11: =3*Assumptions!$B$71*Assumptions!$B$66 -> 48
A12: Units — selling 6-9 months | B12: 0 | C12: 0 | D12: 0 | E12: 0 | F12: 0 | G12: 0 | H12: 0 | I12: 0 | J12: =1*Assumptions!$B$71*Assumptions!$B$67 -> 24 | K12: =2*Assumptions!$B$71*Assumptions!$B$67 -> 48 | L12: =3*Assumptions!$B$71*Assumptions!$B$67 -> 72 | M12: =4*Assumptions!$B$71*Assumptions!$B$67 -> 96 | N12: =4*Assumptions!$B$71*Assumptions!$B$67 -> 96 | O12: =4*Assumptions!$B$71*Assumptions!$B$67 -> 96 | P12: =4*Assumptions!$B$71*Assumptions!$B$67 -> 96 | Q12: =4*Assumptions!$B$71*Assumptions!$B$67 -> 96 | R12: =4*Assumptions!$B$71*Assumptions!$B$67 -> 96 | S12: =4*Assumptions!$B$71*Assumptions!$B$67 -> 96
A13: Units — selling 10+ months | B13: 0 | C13: 0 | D13: 0 | E13: 0 | F13: 0 | G13: 0 | H13: 0 | I13: 0 | J13: 0 | K13: 0 | L13: 0 | M13: 0 | N13: =1*Assumptions!$B$71*Assumptions!$B$68 -> 24 | O13: =2*Assumptions!$B$71*Assumptions!$B$68 -> 48 | P13: =3*Assumptions!$B$71*Assumptions!$B$68 -> 72 | Q13: =4*Assumptions!$B$71*Assumptions!$B$68 -> 96 | R13: =5*Assumptions!$B$71*Assumptions!$B$68 -> 120 | S13: =6*Assumptions!$B$71*Assumptions!$B$68 -> 144
A14: TOTAL HARDWARE UNITS (this month) | B14: =SUM(B10:B13) -> 0 | C14: =SUM(C10:C13) -> 0 | D14: =SUM(D10:D13) -> 0 | E14: =SUM(E10:E13) -> 8 | F14: =SUM(F10:F13) -> 16 | G14: =SUM(G10:G13) -> 32 | H14: =SUM(H10:H13) -> 48 | I14: =SUM(I10:I13) -> 64 | ... S14: =SUM(S10:S13) -> 304 | T14: =SUM(B14:S14) -> 2128
A15: Cumulative Cartridges in Field | B15: =B14 -> 0 | C15: =B15+C14 -> 0 | D15: =C15+D14 -> 0 | E15: =D15+E14 -> 8 | F15: =E15+F14 -> 24 | G15: =F15+G14 -> 56 | H15: =G15+H14 -> 104 | I15: =H15+I14 -> 168 | J15: =I15+J14 -> 256 | ... S15: =R15+S14 -> 2128 | T15: =S15 -> 2128
A17: REFILLS (driven by installed cartridge base)
A18: Cartridges eligible for refill (after lag) | B18: 0 | C18: 0 | D18: =B15 -> 0 | E18: =C15 -> 0 | F18: =D15 -> 0 | G18: =E15 -> 8 | H18: =F15 -> 24 | I18: =G15 -> 56 | J18: =H15 -> 104 | K18: =I15 -> 168 | ... S18: =Q15 -> 1544 | T18: =S18 -> 1544
A19: Theoretical monthly refills | B19: =B18*Assumptions!$B$56 -> 0 | C19: =C18*Assumptions!$B$56 -> 0 | D19: =D18*Assumptions!$B$56 -> 0 | E19: =E18*Assumptions!$B$56 -> 0 | F19: =F18*Assumptions!$B$56 -> 0 | G19: =G18*Assumptions!$B$56 -> 1.976 | H19: =H18*Assumptions!$B$56 -> 5.928 | I19: =I18*Assumptions!$B$56 -> 13.832 | ... S19: =S18*Assumptions!$B$56 -> 381.368 | T19: =SUM(B19:S19) -> 1701.336
A20: Reported refills (after cheating) | B20: =B19*Assumptions!$B$47 -> 0 | C20: =C19*Assumptions!$B$47 -> 0 | D20: =D19*Assumptions!$B$47 -> 0 | E20: =E19*Assumptions!$B$47 -> 0 | F20: =F19*Assumptions!$B$47 -> 0 | G20: =G19*Assumptions!$B$47 -> 1.1856 | H20: =H19*Assumptions!$B$47 -> 3.5568 | I20: =I19*Assumptions!$B$47 -> 8.2992 | ... S20: =S19*Assumptions!$B$47 -> 228.8208 | T20: =SUM(B20:S20) -> 1020.8016
A21: Check: reported refills / eligible cartridges | B21: =IF(B18>0,B20/B18,0) -> 0 | C21: =IF(C18>0,C20/C18,0) -> 0 | D21: =IF(D18>0,D20/D18,0) -> 0 | E21: =IF(E18>0,E20/E18,0) -> 0 | F21: =IF(F18>0,F20/F18,0) -> 0 | G21: =IF(G18>0,G20/G18,0) -> 0.1482 | H21: =IF(H18>0,H20/H18,0) -> 0.1482 | I21: =IF(I18>0,I20/I18,0) -> 0.1482 | ... S21: =IF(S18>0,S20/S18,0) -> 0.1482
A23: REVENUE
A24: Stream 1: Starter Kit Revenue | B24: =B6*Assumptions!$B$36 -> 7992 | C24: =C6*Assumptions!$B$36 -> 7992 | D24: =D6*Assumptions!$B$36 -> 7992 | E24: =1*Assumptions!$B$36+7*Assumptions!$B$35 -> 11492 | F24: =F6*Assumptions!$B$35 -> 11992 | G24: =G6*Assumptions!$B$35 -> 11992 | H24: =H6*Assumptions!$B$35 -> 11992 | I24: =I6*Assumptions!$B$35 -> 11992 | J24: =J6*Assumptions!$B$35 -> 11992 | K24: =K6*Assumptions!$B$35 -> 11992 | L24: =L6*Assumptions!$B$35 -> 11992 | M24: =M6*Assumptions!$B$35 -> 11992 | ... S24: =S6*Assumptions!$B$35 -> 11992 | T24: =SUM(B24:S24) -> 203356
A25: Hardware — Tier 1 units (stages 1-5) | B25: =(B10+B11)*Assumptions!$D$41 -> 0 | C25: =(C10+C11)*Assumptions!$D$41 -> 0 | D25: =(D10+D11)*Assumptions!$D$41 -> 0 | E25: =(E10+E11)*Assumptions!$D$41 -> 5094 | F25: =(F10+F11)*Assumptions!$D$41 -> 10188 | G25: =(G10+G11)*Assumptions!$D$41 -> 20376 | H25: =(H10+H11)*Assumptions!$D$41 -> 30564 | I25: =(I10+I11)*Assumptions!$D$41 -> 40752 | ... S25: =(S10+S11)*Assumptions!$D$41 -> 40752
A26: Hardware — Tier 2 units (stages 6+) | B26: =(B12+B13)*Assumptions!$D$42 -> 0 | C26: =(C12+C13)*Assumptions!$D$42 -> 0 | D26: =(D12+D13)*Assumptions!$D$42 -> 0 | E26: =(E12+E13)*Assumptions!$D$42 -> 0 | F26: =(F12+F13)*Assumptions!$D$42 -> 0 | G26: =(G12+G13)*Assumptions!$D$42 -> 0 | H26: =(H12+H13)*Assumptions!$D$42 -> 0 | I26: =(I12+I13)*Assumptions!$D$42 -> 0 | ... S26: =(S12+S13)*Assumptions!$D$42 -> 132444
A27: Stream 2: Total Hardware Revenue | B27: =B25+B26 -> 0 | C27: =C25+C26 -> 0 | D27: =D25+D26 -> 0 | E27: =E25+E26 -> 5094 | F27: =F25+F26 -> 10188 | G27: =G25+G26 -> 20376 | H27: =H25+H26 -> 30564 | I27: =I25+I26 -> 40752 | ... S27: =S25+S26 -> 173196 | T27: =SUM(B27:S27) -> 1242936
A28: Stream 3: Refill Revenue | B28: =B20*Assumptions!$B$46 -> 0 | C28: =C20*Assumptions!$B$46 -> 0 | D28: =D20*Assumptions!$B$46 -> 0 | E28: =E20*Assumptions!$B$46 -> 0 | F28: =F20*Assumptions!$B$46 -> 0 | G28: =G20*Assumptions!$B$46 -> 3.5568 | H28: =H20*Assumptions!$B$46 -> 10.6704 | I28: =I20*Assumptions!$B$46 -> 24.8976 | ... S28: =S20*Assumptions!$B$46 -> 686.4624 | T28: =SUM(B28:S28) -> 3062.4048
A30: TOTAL REVENUE | B30: =B24+B27+B28 -> 7992 | C30: =C24+C27+C28 -> 7992 | D30: =D24+D27+D28 -> 7992 | E30: =E24+E27+E28 -> 16586 | F30: =F24+F27+F28 -> 22180 | G30: =G24+G27+G28 -> 32371.557 | H30: =H24+H27+H28 -> 42566.67 | I30: =I24+I27+I28 -> 52768.898 | ... S30: =S24+S27+S28 -> 185874.46 | T30: =SUM(B30:S30) -> 1449354.4
A32: COST OF GOODS SOLD
A33: Starter Kit COGS | B33: =B6*Assumptions!$B$31 -> 6415.8452 | C33: =C6*Assumptions!$B$31 -> 6415.8452 | D33: =D6*Assumptions!$B$31 -> 6415.8452 | E33: =E6*Assumptions!$B$31 -> 6415.8452 | F33: =F6*Assumptions!$B$31 -> 6415.8452 | G33: =G6*Assumptions!$B$31 -> 6415.8452 | H33: =H6*Assumptions!$B$31 -> 6415.8452 | I33: =I6*Assumptions!$B$31 -> 6415.8452 | ... S33: =S6*Assumptions!$B$31 -> 6415.8452 | T33: =SUM(B33:S33) -> 115485.21
A34: Hardware COGS | B34: =B14*Assumptions!$B$30 -> 0 | C34: =C14*Assumptions!$B$30 -> 0 | D34: =D14*Assumptions!$B$30 -> 0 | E34: =E14*Assumptions!$B$30 -> 2000.672 | F34: =F14*Assumptions!$B$30 -> 4001.344 | G34: =G14*Assumptions!$B$30 -> 8002.688 | H34: =H14*Assumptions!$B$30 -> 12004.032 | I34: =I14*Assumptions!$B$30 -> 16005.376 | ... S34: =S14*Assumptions!$B$30 -> 76025.536 | T34: =SUM(B34:S34) -> 532178.75
A36: TOTAL COGS | B36: =B33+B34 -> 6415.8452 | C36: =C33+C34 -> 6415.8452 | D36: =D33+D34 -> 6415.8452 | E36: =E33+E34 -> 8416.5172 | F36: =F33+F34 -> 10417.189 | G36: =G33+G34 -> 14418.533 | H36: =H33+H34 -> 18419.877 | I36: =I33+I34 -> 22421.221 | ... S36: =S33+S34 -> 82441.381 | T36: =SUM(B36:S36) -> 647663.97
A38: GROSS PROFIT | B38: =B30-B36 -> 1576.1548 | C38: =C30-C36 -> 1576.1548 | D38: =D30-D36 -> 1576.1548 | E38: =E30-E36 -> 8169.4828 | F38: =F30-F36 -> 11762.811 | G38: =G30-G36 -> 17953.024 | H38: =H30-H36 -> 24146.793 | I38: =I30-I36 -> 30347.676 | ... S38: =S30-S36 -> 103433.08 | T38: =SUM(B38:S38) -> 801690.44
A39: Gross Margin % | B39: =IF(B30>0,B38/B30,0) -> 0.19721657 | C39: =IF(C30>0,C38/C30,0) -> 0.19721657 | D39: =IF(D30>0,D38/D30,0) -> 0.19721657 | E39: =IF(E30>0,E38/E30,0) -> 0.49255292 | F39: =IF(F30>0,F38/F30,0) -> 0.53033412 | G39: =IF(G30>0,G38/G30,0) -> 0.55459253 | H39: =IF(H30>0,H38/H30,0) -> 0.56726995 | I39: =IF(I30>0,I38/I30,0) -> 0.57510537 | ... T39: =IF(T30>0,T38/T30,0) -> 0.55313624
A41: OPERATING EXPENSES
A42: Monthly OpEx | B42: =Assumptions!$B$85 -> 13750 | C42: =Assumptions!$B$85 -> 13750 | D42: =Assumptions!$B$85 -> 13750 | E42: =Assumptions!$B$85 -> 13750 | F42: =Assumptions!$B$85 -> 13750 | G42: =Assumptions!$B$85 -> 13750 | H42: =Assumptions!$C$85 -> 17350 | I42: =Assumptions!$C$85 -> 17350 | J42: =Assumptions!$C$85 -> 17350 | K42: =Assumptions!$C$85 -> 17350 | L42: =Assumptions!$C$85 -> 17350 | M42: =Assumptions!$C$85 -> 17350 | N42: =Assumptions!$D$85 -> 21000 | O42: =Assumptions!$D$85 -> 21000 | P42: =Assumptions!$D$85 -> 21000 | Q42: =Assumptions!$D$85 -> 21000 | R42: =Assumptions!$D$85 -> 21000 | S42: =Assumptions!$D$85 -> 21000 | T42: =SUM(B42:S42) -> 312600
A44: NET INCOME (LOSS) | B44: =B38-B42 -> -12173.845 | C44: =C38-C42 -> -12173.845 | D44: =D38-D42 -> -12173.845 | E44: =E38-E42 -> -5580.5172 | F44: =F38-F42 -> -1987.1892 | G44: =G38-G42 -> 4203.0236 | H44: =H38-H42 -> 6796.7932 | I44: =I38-I42 -> 12997.676 | ... S44: =S38-S42 -> 82433.081 | T44: =SUM(B44:S44) -> 489090.44
A45: Net Margin % | B45: =IF(B30>0,B44/B30,0) -> -1.5232539 | C45: =IF(C30>0,C44/C30,0) -> -1.5232539 | D45: =IF(D30>0,D44/D30,0) -> -1.5232539 | E45: =IF(E30>0,E44/E30,0) -> -0.3364595 | F45: =IF(F30>0,F44/F30,0) -> -0.089593742 | G45: =IF(G30>0,G44/G30,0) -> 0.12983693 | H45: =IF(H30>0,H44/H30,0) -> 0.15967406 | I45: =IF(I30>0,I44/I30,0) -> 0.24631321 | ... T45: =IF(T30>0,T44/T30,0) -> 0.337454
A47: CUMULATIVE NET POSITION
A48: Cumulative P&L | B48: =B44 -> -12173.845 | C48: =B48+C44 -> -24347.69 | D48: =C48+D44 -> -36521.536 | E48: =D48+E44 -> -42102.053 | F48: =E48+F44 -> -44089.242 | G48: =F48+G44 -> -39886.218 | H48: =G48+H44 -> -33089.425 | I48: =H48+I44 -> -20091.749 | J48: =I48+J44 -> 169.6524 | ... S48: =R48+S44 -> 489090.44
A50: MONTH 18 ANNUALIZED RUN RATE
A51: Revenue Run Rate | B51: =S30*12 -> 2230493.5
A52: Gross Profit Run Rate | B52: =S38*12 -> 1241197
...

Sheet Sensitivity
A1: ∆P — Sensitivity Analysis
A2: Worst Case → Conservative Base (our plan) → Upside
B3: Worst Case | C3: Conservative Base | D3: Upside
A5: SCENARIO ASSUMPTIONS
A6: Partners / month | B6: 5 | C6: 8 | D6: 12
A7: Hardware delay (months) | B7: 3 | C7: 3 | D7: 2
A8: Refill lag after sale (months) | B8: 3 | C8: 2 | D8: 1
A9: Unit ramp (selling mo 1-2/3-5/6-9/10+) | B9: 1/1/2/2 | C9: 1/2/3/3 | D9: 2/3/4/5
A10: Blended refill rate / cartridge / month | B10: 0.15 | C10: 0.25 | D10: 0.4
A11: Capture rate | B11: 0.5 | C11: 0.6 | D11: 0.75
A12: Monthly OpEx (avg) | B12: 12000 | C12: 13500 | D12: 15000
A14: 18-MONTH RESULTS
A15: Total Partners | B15: 90 | C15: 144 | D15: 216
A16: Total Hardware Units Sold | B16: 875 | C16: 2128 | D16: 5652
A17: Cartridges in Field (month 18) | B17: 875 | C17: 2128 | D17: 5652
A18: Eligible for Refill (month 18) | B18: 530 | C18: 1544 | D18: 4884
A19: Total Reported Refills (18 mo) | B19: 168 | C19: 1033 | D19: 7528
A20: Monthly Refills at Month 18 | B20: 40 | C20: 232 | D20: 1465
A22: Starter Kit Revenue | B22: 122410 | C22: 203356 | D22: 311284
A23: Hardware Revenue | B23: 510461 | C23: 1242936 | D23: 3301421
A24: Refill Revenue | B24: 504 | C24: 3100 | D24: 22583
A25: TOTAL REVENUE | B25: 633375 | C25: 1449392 | D25: 3635288
A27: Total COGS | B27: 299575 | C27: 666416 | D27: 1631844
A28: GROSS PROFIT | B28: 333800 | C28: 782976 | D28: 2003444
... A37: Break-even Month | B37: 14 | C37: 9 | D37: 5

Sheet Use of Funds
A1: ∆P — Use of Funds ($250K Seed Round)
A3: ALLOCATION
A4: Category | B4: Amount | C4: % of Total | D4: Purpose
A5: Initial Inventory (40 starter + 80 consumer kits) | B5: 55000 | C5: =B5/B12 -> 0.22 | D5: First PFF batch — conservative order size
A6: Operating Expenses (6 months runway) | B6: 82500 | C6: =B6/B12 -> 0.33 | D6: Recruiter, warehouse, insurance, software, legal at conservative OpEx
A7: Marketing & Partner Acquisition | B7: 25000 | C7: =B7/B12 -> 0.1 | D7: Meta ads, trade shows — conservative spend
A8: Warehouse Setup & Equipment | B8: 15000 | C8: =B8/B12 -> 0.06 | D8: FL storage, shelving, nitrogen fill station
A9: Working Capital / Reorder Buffer | B9: 42000 | C9: =B9/B12 -> 0.168 | D9: Second inventory order + buffer for slow collections
A10: Legal & Compliance | B10: 12000 | C10: =B10/B12 -> 0.048 | D10: Partner agreements, product liability, customs broker
A11: Contingency Reserve (7.5%) | B11: 18500 | C11: =B11/B12 -> 0.074 | D11: FX swings, tariff changes, unexpected costs, slower ramp
A12: TOTAL RAISE | B12: =SUM(B5:B11) -> 250000 | C12: 1
A14: RUNWAY ANALYSIS
A15: Monthly burn (months 1-6, no revenue offset) | B15: =Assumptions!B85 -> 13750
A16: Pure runway at burn (months) | B16: =B12/B15 -> 18.181818
A17: Break-even month (conservative base) | B17: 9

Sheet Market & TAM
A1: ∆P — Total Addressable Market
A3: US MARKET SEGMENTS
A4: Segment | B4: Estimated Count | C4: Source
A5: Aircraft mechanics & technicians | B5: 160800 | C5: BLS (2024)
A6: FAA certified repair stations | B6: 3700 | C6: FAA
A7: Fixed Base Operators (FBOs) | B7: 850 | C7: GlobalAir
A8: Auto repair & maintenance | B8: 176000 | C8: BLS / Statista
A9: Auto body shops | B9: 95000 | C9: Multiple sources
A10: Motorcycle / powersports | B10: 15781 | C10: IBISWorld (2025)
A11: Golf cart dealers | B11: 3400 | C11: IBISWorld
A12: RV repair | B12: 9205 | C12: Directory (2025)
A13: Bicycle / e-bike shops | B13: 5000 | C13: NBDA / Zippia
A14: Off-road / 4x4 shops | B14: 6500 | C14: Estimated
A15: Total Broad TAM | B15: =SUM(B5:B14) -> 476236
A16: Realistic Addressable | B16: 40000
A18: PENETRATION (Conservative Base: 8/mo)
A19: Year 1 partners | B19: 96
A20: % of addressable | B20: =B19/B16 -> 0.0024
A21: 18-month partners | B21: 144
A22: % of addressable | B22: =B21/B16 -> 0.0036
A24: COMPETITIVE LANDSCAPE
A25: Key finding: | B25: No national mobile nitrogen service network exists
A26: Moat: | B26: Hazmat shipping = natural local monopoly for partners
